[2024-08-20T04:53:07.733+0000] {local_task_job_runner.py:123} INFO - ::group::Pre task execution logs
[2024-08-20T04:53:07.752+0000] {taskinstance.py:2603} INFO - Dependencies all met for dep_context=non-requeueable deps ti=<TaskInstance: fetch_and_store_DE_books.insert_book_data scheduled__2024-06-28T00:00:00+00:00 [queued]>
[2024-08-20T04:53:07.763+0000] {taskinstance.py:2603} INFO - Dependencies all met for dep_context=requeueable deps ti=<TaskInstance: fetch_and_store_DE_books.insert_book_data scheduled__2024-06-28T00:00:00+00:00 [queued]>
[2024-08-20T04:53:07.764+0000] {taskinstance.py:2856} INFO - Starting attempt 2 of 2
[2024-08-20T04:53:07.782+0000] {taskinstance.py:2879} INFO - Executing <Task(PythonOperator): insert_book_data> on 2024-06-28 00:00:00+00:00
[2024-08-20T04:53:07.793+0000] {warnings.py:112} WARNING - /home/***/.local/lib/python3.12/site-packages/***/task/task_runner/standard_task_runner.py:70: DeprecationWarning: This process (pid=1618) is multi-threaded, use of fork() may lead to deadlocks in the child.
  pid = os.fork()

[2024-08-20T04:53:07.795+0000] {standard_task_runner.py:72} INFO - Started process 1626 to run task
[2024-08-20T04:53:07.795+0000] {standard_task_runner.py:104} INFO - Running: ['***', 'tasks', 'run', 'fetch_and_store_DE_books', 'insert_book_data', 'scheduled__2024-06-28T00:00:00+00:00', '--job-id', '194', '--raw', '--subdir', 'DAGS_FOLDER/app.py', '--cfg-path', '/tmp/tmpbp7iqx02']
[2024-08-20T04:53:07.797+0000] {standard_task_runner.py:105} INFO - Job 194: Subtask insert_book_data
[2024-08-20T04:53:07.882+0000] {task_command.py:467} INFO - Running <TaskInstance: fetch_and_store_DE_books.insert_book_data scheduled__2024-06-28T00:00:00+00:00 [running]> on host 668944ed7238
[2024-08-20T04:53:08.038+0000] {taskinstance.py:3122} INFO - Exporting env vars: AIRFLOW_CTX_DAG_OWNER='***' AIRFLOW_CTX_DAG_ID='fetch_and_store_DE_books' AIRFLOW_CTX_TASK_ID='insert_book_data' AIRFLOW_CTX_EXECUTION_DATE='2024-06-28T00:00:00+00:00' AIRFLOW_CTX_TRY_NUMBER='2' AIRFLOW_CTX_DAG_RUN_ID='scheduled__2024-06-28T00:00:00+00:00'
[2024-08-20T04:53:08.041+0000] {logging_mixin.py:190} INFO - Task instance is in running state
[2024-08-20T04:53:08.042+0000] {logging_mixin.py:190} INFO -  Previous state of the Task instance: queued
[2024-08-20T04:53:08.043+0000] {logging_mixin.py:190} INFO - Current task name:insert_book_data state:running start_date:2024-08-20 04:53:07.753379+00:00
[2024-08-20T04:53:08.044+0000] {logging_mixin.py:190} INFO - Dag name:fetch_and_store_DE_books and current dag run status:running
[2024-08-20T04:53:08.045+0000] {taskinstance.py:731} INFO - ::endgroup::
[2024-08-20T04:53:08.059+0000] {taskinstance.py:3301} ERROR - Task failed with exception
Traceback (most recent call last):
  File "/home/airflow/.local/lib/python3.12/site-packages/airflow/models/taskinstance.py", line 767, in _execute_task
    result = _execute_callable(context=context, **execute_callable_kwargs)
             ^^^^^^^^^^^^^^^^^^^^^^^^^^^^^^^^^^^^^^^^^^^^^^^^^^^^^^^^^^^^^
  File "/home/airflow/.local/lib/python3.12/site-packages/airflow/models/taskinstance.py", line 733, in _execute_callable
    return ExecutionCallableRunner(
           ^^^^^^^^^^^^^^^^^^^^^^^^
  File "/home/airflow/.local/lib/python3.12/site-packages/airflow/utils/operator_helpers.py", line 252, in run
    return self.func(*args, **kwargs)
           ^^^^^^^^^^^^^^^^^^^^^^^^^^
  File "/home/airflow/.local/lib/python3.12/site-packages/airflow/models/baseoperator.py", line 406, in wrapper
    return func(self, *args, **kwargs)
           ^^^^^^^^^^^^^^^^^^^^^^^^^^^
  File "/home/airflow/.local/lib/python3.12/site-packages/airflow/operators/python.py", line 238, in execute
    return_value = self.execute_callable()
                   ^^^^^^^^^^^^^^^^^^^^^^^
  File "/home/airflow/.local/lib/python3.12/site-packages/airflow/operators/python.py", line 256, in execute_callable
    return runner.run(*self.op_args, **self.op_kwargs)
           ^^^^^^^^^^^^^^^^^^^^^^^^^^^^^^^^^^^^^^^^^^^
  File "/home/airflow/.local/lib/python3.12/site-packages/airflow/utils/operator_helpers.py", line 252, in run
    return self.func(*args, **kwargs)
           ^^^^^^^^^^^^^^^^^^^^^^^^^^
  File "/opt/airflow/dags/app.py", line 101, in insert_book_data_into_postgres
    raise ValueError("No book data found")
ValueError: No book data found
[2024-08-20T04:53:08.074+0000] {logging_mixin.py:190} INFO - Task instance in failure state
[2024-08-20T04:53:08.075+0000] {logging_mixin.py:190} INFO - Task start:2024-08-20 04:53:07.753379+00:00 end:2024-08-20 04:53:08.073444+00:00 duration:0.320065
[2024-08-20T04:53:08.076+0000] {logging_mixin.py:190} INFO - Task:<Task(PythonOperator): insert_book_data> dag:<DAG: fetch_and_store_DE_books> dagrun:<DagRun fetch_and_store_DE_books @ 2024-06-28 00:00:00+00:00: scheduled__2024-06-28T00:00:00+00:00, state:running, queued_at: 2024-08-20 04:41:43.901155+00:00. externally triggered: False>
[2024-08-20T04:53:08.076+0000] {logging_mixin.py:190} INFO - Failure caused by No book data found
[2024-08-20T04:53:08.077+0000] {taskinstance.py:1225} INFO - Marking task as FAILED. dag_id=fetch_and_store_DE_books, task_id=insert_book_data, run_id=scheduled__2024-06-28T00:00:00+00:00, execution_date=20240628T000000, start_date=20240820T045307, end_date=20240820T045308
[2024-08-20T04:53:08.093+0000] {taskinstance.py:340} INFO - ::group::Post task execution logs
[2024-08-20T04:53:08.094+0000] {standard_task_runner.py:124} ERROR - Failed to execute job 194 for task insert_book_data (No book data found; 1626)
Traceback (most recent call last):
  File "/home/airflow/.local/lib/python3.12/site-packages/airflow/task/task_runner/standard_task_runner.py", line 117, in _start_by_fork
    ret = args.func(args, dag=self.dag)
          ^^^^^^^^^^^^^^^^^^^^^^^^^^^^^
  File "/home/airflow/.local/lib/python3.12/site-packages/airflow/cli/cli_config.py", line 49, in command
    return func(*args, **kwargs)
           ^^^^^^^^^^^^^^^^^^^^^
  File "/home/airflow/.local/lib/python3.12/site-packages/airflow/utils/cli.py", line 115, in wrapper
    return f(*args, **kwargs)
           ^^^^^^^^^^^^^^^^^^
  File "/home/airflow/.local/lib/python3.12/site-packages/airflow/cli/commands/task_command.py", line 483, in task_run
    task_return_code = _run_task_by_selected_method(args, _dag, ti)
                       ^^^^^^^^^^^^^^^^^^^^^^^^^^^^^^^^^^^^^^^^^^^^
  File "/home/airflow/.local/lib/python3.12/site-packages/airflow/cli/commands/task_command.py", line 256, in _run_task_by_selected_method
    return _run_raw_task(args, ti)
           ^^^^^^^^^^^^^^^^^^^^^^^
  File "/home/airflow/.local/lib/python3.12/site-packages/airflow/cli/commands/task_command.py", line 341, in _run_raw_task
    return ti._run_raw_task(
           ^^^^^^^^^^^^^^^^^
  File "/home/airflow/.local/lib/python3.12/site-packages/airflow/utils/session.py", line 97, in wrapper
    return func(*args, session=session, **kwargs)
           ^^^^^^^^^^^^^^^^^^^^^^^^^^^^^^^^^^^^^^
  File "/home/airflow/.local/lib/python3.12/site-packages/airflow/models/taskinstance.py", line 2995, in _run_raw_task
    return _run_raw_task(
           ^^^^^^^^^^^^^^
  File "/home/airflow/.local/lib/python3.12/site-packages/airflow/models/taskinstance.py", line 273, in _run_raw_task
    TaskInstance._execute_task_with_callbacks(
  File "/home/airflow/.local/lib/python3.12/site-packages/airflow/models/taskinstance.py", line 3149, in _execute_task_with_callbacks
    result = self._execute_task(context, task_orig)
             ^^^^^^^^^^^^^^^^^^^^^^^^^^^^^^^^^^^^^^
  File "/home/airflow/.local/lib/python3.12/site-packages/airflow/models/taskinstance.py", line 3173, in _execute_task
    return _execute_task(self, context, task_orig)
           ^^^^^^^^^^^^^^^^^^^^^^^^^^^^^^^^^^^^^^^
  File "/home/airflow/.local/lib/python3.12/site-packages/airflow/models/taskinstance.py", line 767, in _execute_task
    result = _execute_callable(context=context, **execute_callable_kwargs)
             ^^^^^^^^^^^^^^^^^^^^^^^^^^^^^^^^^^^^^^^^^^^^^^^^^^^^^^^^^^^^^
  File "/home/airflow/.local/lib/python3.12/site-packages/airflow/models/taskinstance.py", line 733, in _execute_callable
    return ExecutionCallableRunner(
           ^^^^^^^^^^^^^^^^^^^^^^^^
  File "/home/airflow/.local/lib/python3.12/site-packages/airflow/utils/operator_helpers.py", line 252, in run
    return self.func(*args, **kwargs)
           ^^^^^^^^^^^^^^^^^^^^^^^^^^
  File "/home/airflow/.local/lib/python3.12/site-packages/airflow/models/baseoperator.py", line 406, in wrapper
    return func(self, *args, **kwargs)
           ^^^^^^^^^^^^^^^^^^^^^^^^^^^
  File "/home/airflow/.local/lib/python3.12/site-packages/airflow/operators/python.py", line 238, in execute
    return_value = self.execute_callable()
                   ^^^^^^^^^^^^^^^^^^^^^^^
  File "/home/airflow/.local/lib/python3.12/site-packages/airflow/operators/python.py", line 256, in execute_callable
    return runner.run(*self.op_args, **self.op_kwargs)
           ^^^^^^^^^^^^^^^^^^^^^^^^^^^^^^^^^^^^^^^^^^^
  File "/home/airflow/.local/lib/python3.12/site-packages/airflow/utils/operator_helpers.py", line 252, in run
    return self.func(*args, **kwargs)
           ^^^^^^^^^^^^^^^^^^^^^^^^^^
  File "/opt/airflow/dags/app.py", line 101, in insert_book_data_into_postgres
    raise ValueError("No book data found")
ValueError: No book data found
[2024-08-20T04:53:08.143+0000] {local_task_job_runner.py:261} INFO - Task exited with return code 1
[2024-08-20T04:53:08.161+0000] {taskinstance.py:3891} INFO - 0 downstream tasks scheduled from follow-on schedule check
[2024-08-20T04:53:08.163+0000] {local_task_job_runner.py:240} INFO - ::endgroup::
